<?xml version="1.0"?>
<robot xmlns:xacro="http://www.ros.org/wiki/xacro" >

  <!-- zach, changed all filename to file://$(find my_bot)-->
  <xacro:include filename="inertial_macros.xacro"/>
  <!-- zach -->
  <xacro:macro name="leo" 
               params="default_antenna:=false
                       rockers_fixed:=true
                       footprint_link:=true
                       link_prefix:=''
                       joint_prefix:=''
                       imu_translation:='0.0628 -0.0314 -0.0393'">

    <xacro:macro name="rocker_link" params="name">
      <link name="${link_prefix}rocker_${name}_link">
        <inertial>
          <mass value="1.387336"/>
          <origin xyz="0 0.01346 -0.06506"/>
          <inertia
            ixx="0.002956" ixy="-0.000001489324" ixz="-0.000008103407"
            iyy="0.02924"  iyz="0.00007112"
            izz="0.02832"/>
        </inertial>
        <visual>
          <geometry>
            <mesh filename="file://$(find my_bot)/models/Rocker.dae"/>
            <mesh filename="package://my_bot/models/Rocker.dae"/>
          </geometry>
        </visual>
        <collision>
          <geometry>
            <mesh filename="file://$(find my_bot)/models/Rocker_outline.stl"/>
            <mesh filename="package://my_bot/models/Rocker_outline.stl"/>
          </geometry>
        </collision>
      </link>
    </xacro:macro>

    <xacro:macro name="wheel_link" params="name model"> 
      <link name="${link_prefix}wheel_${name}_link">
        <inertial>
          <mass value="0.283642"/>
          <origin xyz="0 0.030026 0"/>
          <inertia
            ixx="0.000391"  ixy="0.00000123962" ixz="5.52582e-7"
            iyy="0.0004716" iyz="-0.000002082042"
            izz="0.000391"/>
        </inertial>
        <visual>
          <geometry>
            <mesh filename="file://$(find my_bot)/models/Wheel${model}.dae"/>
            <mesh filename="package://my_bot/models/Wheel${model}.dae"/>
          </geometry>
        </visual>
        <collision>
          <origin xyz="0 0.04485 0" rpy="${pi/2} 0 0"/>
          <geometry>
            <cylinder radius="0.0625" length="0.04"/>
          </geometry>
        </collision>
        <collision>
          <geometry>
            <mesh filename="file://$(find my_bot)/models/Wheel_outline.stl"/>
            <mesh filename="package://my_bot/models/Wheel_outline.stl"/>
          </geometry>
        </collision>
      </link>
    </xacro:macro>

    <!-- zach -->
    <material name="red">
          <color rgba="1 0 0 1"/>
    </material>

    <material name="blue">
          <color rgba="0 0 1 1"/>
    </material>
    <!-- zach -->

    <!-- LINKS -->
    <xacro:if value="${footprint_link}">
      <link name="${link_prefix}base_footprint"/>
    </xacro:if>

    <link name="${link_prefix}base_link">
      <inertial>
        <mass value="1.584994"/>
        <origin xyz="-0.019662 0.011643 -0.031802"/>
        <inertia
          ixx="0.01042" ixy="0.001177" ixz="-0.0008871"
          iyy="0.01045" iyz="0.0002226"
          izz="0.01817"/>
      </inertial>
      <visual>
        <geometry>
          <mesh filename="file://$(find my_bot)/models/Chassis.dae"/>
          <mesh filename="package://my_bot/models/Chassis.dae"/>
        </geometry>
      </visual>
      <collision>
        <geometry>
          <mesh filename="file://$(find my_bot)/models/Chassis_outline.stl"/>
          <mesh filename="package://my_bot/models/Chassis_outline.stl"/>
        </geometry>
      </collision>
    </link>

    <xacro:rocker_link name="L"/>
    <xacro:rocker_link name="R"/>
    <xacro:wheel_link name="FL" model="A"/>
    <xacro:wheel_link name="RL" model="A"/>
    <xacro:wheel_link name="FR" model="B"/>
    <xacro:wheel_link name="RR" model="B"/>

    <xacro:if value="${default_antenna}">
      <link name="${link_prefix}antenna_link">
        <inertial>
          <mass value="0.001237"/>
          <origin xyz="0 0 0.028828"/>
          <inertia
            ixx="2.5529e-7" ixy="0.0" ixz="0.0"
            iyy="2.5529e-7" iyz="0.0"
            izz="1.354e-8"/>
        </inertial>
        <visual>
          <geometry>
            <mesh filename="file://$(find my_bot)/models/Antenna.dae"/>
            <mesh filename="package://my_bot/models/Antenna.dae"/>
          </geometry>
        </visual>
        <collision>
          <origin xyz="0 0 0.028"/>
          <geometry>
            <cylinder radius="0.0055" length="0.056"/>
          </geometry>
        </collision>
      </link>
    </xacro:if>

    <!-- <link name="${link_prefix}camera_frame"/>
    <link name="${link_prefix}camera_optical_frame"/>
    <link name="${link_prefix}imu_frame"/> -->

    <!-- JOINTS -->

    <xacro:if value="${footprint_link}">
      <joint name="${joint_prefix}base_joint" type="fixed">
        <origin xyz="0 0 0.19783" rpy="0 0 0"/>
        <parent link="${link_prefix}base_footprint"/>
        <child link="${link_prefix}base_link"/>
      </joint>
    </xacro:if>

    <xacro:if value="${rockers_fixed}">
      <xacro:property name="rockers_joint_type" value="fixed"/>
    </xacro:if>
    <xacro:unless value="${rockers_fixed}">
      <xacro:property name="rockers_joint_type" value="revolute"/>
    </xacro:unless>

    <joint name="${joint_prefix}rocker_L_joint" type="${rockers_joint_type}">
      <origin xyz="0.00263 0.14167 -0.04731" rpy="0 0 ${pi}"/>
      <parent link="${link_prefix}base_link"/>
      <child link="${link_prefix}rocker_L_link"/>
      <axis xyz="0 1 0"/>
      <limit effort="100.0" lower="-0.24" upper="0.24" velocity="100.0"/>
      <dynamics friction="1.0" damping="0.1"/>
    </joint>

    <joint name="${joint_prefix}rocker_R_joint" type="${rockers_joint_type}">
      <origin xyz="0.00263 -0.14167 -0.04731" rpy="0 0 0"/>
      <parent link="${link_prefix}base_link"/>
      <child link="${link_prefix}rocker_R_link"/>
      <axis xyz="0 1 0"/>
      <limit effort="100.0" lower="-0.24" upper="0.24" velocity="100.0"/>
      <dynamics friction="1.0" damping="0.1"/> 
      <mimic joint="rocker_L_joint"/>
    </joint>

    <joint name="${joint_prefix}wheel_FL_joint" type="continuous">
      <origin xyz="-0.15256 -0.08214 -0.08802" rpy="0 0 0"/>
      <parent link="${link_prefix}rocker_L_link"/>
      <child link="${link_prefix}wheel_FL_link"/>
      <axis xyz="0 -1 0"/>
      <!-- <limit effort="2.0" velocity="6.0"/>
      <dynamics friction="0.3125" damping="0.1"/> -->
    </joint>

    <joint name="${joint_prefix}wheel_RL_joint" type="continuous">
      <origin xyz="0.15256 -0.08214 -0.08802" rpy="0 0 0"/>
      <parent link="${link_prefix}rocker_L_link"/>
      <child link="${link_prefix}wheel_RL_link"/>
      <axis xyz="0 -1 0"/>
      <!-- <limit effort="2.0" velocity="6.0"/>
      <dynamics friction="0.3125" damping="0.1"/> -->
    </joint>

    <joint name="${joint_prefix}wheel_FR_joint" type="continuous">
      <origin xyz="0.15256 -0.08214 -0.08802" rpy="0 0 0"/>
      <parent link="${link_prefix}rocker_R_link"/>
      <child link="${link_prefix}wheel_FR_link"/>
      <axis xyz="0 1 0"/>
      <!-- <limit effort="2.0" velocity="6.0"/>
      <dynamics friction="0.3125" damping="0.1"/> -->
    </joint>

    <joint name="${joint_prefix}wheel_RR_joint" type="continuous">
      <origin xyz="-0.15256 -0.08214 -0.08802" rpy="0 0 0"/>
      <parent link="${link_prefix}rocker_R_link"/>
      <child link="${link_prefix}wheel_RR_link"/>
      <axis xyz="0 1 0"/>
      <!-- <limit effort="2.0" velocity="6.0"/>
      <dynamics friction="0.3125" damping="0.1"/>  -->
    </joint>

    <xacro:if value="${default_antenna}">
      <joint name="${joint_prefix}antenna_joint" type="fixed">
        <origin xyz="-0.0052 0.056 -0.0065" rpy="0 0 0"/>
        <parent link="${link_prefix}base_link"/>
        <child link="${link_prefix}antenna_link"/>
      </joint>
    </xacro:if>

    <!-- <joint name="${joint_prefix}camera_joint" type="fixed">
      <origin xyz="0.0971 0 -0.0427" rpy="0 0.2094 0"/>
      <parent link="${link_prefix}base_link"/>
      <child link="${link_prefix}camera_frame"/>
    </joint>

    <joint name="${joint_prefix}camera_optical_joint" type="fixed">
      <origin xyz="0 0 0" rpy="-${pi/2} 0.0 -${pi/2}"/>
      <parent link="${link_prefix}camera_frame"/>
      <child link="${link_prefix}camera_optical_frame"/>
    </joint>

    <joint name="${joint_prefix}imu_joint" type="fixed">
      <origin xyz="${imu_translation}" rpy="0 0 0"/>
      <parent link="${link_prefix}base_link"/>
      <child link="${link_prefix}imu_frame"/>
    </joint> -->
    

    <!-- wheel ODE properties -->
    <!-- <gazebo reference="${link_prefix}wheel_FL_link">
      <kp>1e6</kp>
      <kd>100.0</kd>
      <mu1>3.0</mu1>
      <mu2>1.0</mu2>
      <fdir1>1 0 0</fdir1>
      <minDepth>0.003</minDepth>
    </gazebo>

    <gazebo reference="${link_prefix}wheel_FR_link">
      <kp>1e6</kp>
      <kd>100.0</kd>
      <mu1>3.0</mu1>
      <mu2>1.0</mu2>
      <fdir1>1 0 0</fdir1>
      <minDepth>0.003</minDepth>
    </gazebo>

    <gazebo reference="${link_prefix}wheel_RL_link">
      <kp>1e6</kp>
      <kd>100.0</kd>
      <mu1>3.0</mu1>
      <mu2>1.0</mu2>
      <fdir1>1 0 0</fdir1>
      <minDepth>0.003</minDepth>
    </gazebo>

    <gazebo reference="${link_prefix}wheel_RR_link">
      <kp>1e6</kp>
      <kd>100.0</kd>
      <mu1>3.0</mu1>
      <mu2>1.0</mu2>
      <fdir1>1 0 0</fdir1>
      <minDepth>0.003</minDepth>
    </gazebo> -->


  </xacro:macro>
</robot>